<?xml version="1.0" ?>

<robot name="myexample" xmlns:xacro="http://www.ros.org/wiki/xacro">
    <link name="base_link">
        <visual>
            <origin rpy="0 0 0" xyz="0 0 10"/>
            <geometry>
                <box size="1 1 1"/>
            </geometry>
        </visual>
        <inertial>
          <mass value="3.42"/>
          <origin rpy="0 0 0" xyz="0.0 0.0 0.121825"/>
          <inertia ixx="0.0217284832211" ixy="0.0" ixz="0.0" iyy="0.0217284832211" iyz="0.0" izz="0.00961875"/>
        </inertial>
    </link>

    <joint name="joint_0" type="revolute">
        <axis xyz="1 0 0" />
        <limit effort="1000.0" lower="-3.14" upper="3.14" velocity="0.5" />
        <origin rpy="0 0 0" xyz="0 0 0"/>
        <parent link="base_link"/>
        <child link="link1"/>
    </joint>

    <link name="link1">
        <visual>
                <origin rpy="0 0 0" xyz="0 0 0.0"/>
                <geometry>
                    <cylinder radius="0.35" length="0.4"/>
                </geometry>
        </visual>
        <inertial>
          <mass value="3.42"/>
          <origin rpy="0 0 0" xyz="0.0 0.0 0.121825"/>
          <inertia ixx="0.0217284832211" ixy="0.0" ixz="0.0" iyy="0.0217284832211" iyz="0.0" izz="0.00961875"/>
        </inertial>
    </link>

    <joint name="joint_1" type="revolute">
        <axis xyz="1 0 0" />
        <limit effort="1000.0" lower="-3.14" upper="3.14" velocity="0.5" />
        <origin rpy="0 0 0" xyz="0 0 1.0"/>
        <parent link="link1"/>
        <child link="link2"/>
    </joint>

    <link name="link2">
        <visual>
            <origin rpy="0 0 0" xyz="0 0 0.2"/>
                <geometry>
                    <cylinder radius="0.35" length="0.4"/>
                </geometry>
        </visual>
        <inertial>
          <mass value="3.42"/>
          <origin rpy="0 0 0" xyz="0.0 0.0 0.121825"/>
          <inertia ixx="0.0217284832211" ixy="0.0" ixz="0.0" iyy="0.0217284832211" iyz="0.0" izz="0.00961875"/>
        </inertial>
    </link>
</robot>
